<?xml version="1.0" ?>
<sdf version="1.4">
  <world name="default">
    <include>
      <uri>model://sun</uri>
    </include>

    <model name="my_model">
      <pose>0 0.5 0.5 0 0 0</pose>
      <static>false</static>
      <link name="link">
        <inertial>
          <mass>1.0</mass>
          <inertia> <!-- interias are tricky to compute -->
            <!-- http://answers.gazebosim.org/question/4372/the-inertia-matrix-explained/ -->
            <ixx>0.083</ixx>       <!-- for a box: ixx = 0.083 * mass * (y*y + z*z) -->
            <ixy>0.0</ixy>         <!-- for a box: ixy = 0 -->
            <ixz>0.0</ixz>         <!-- for a box: ixz = 0 -->
            <iyy>0.083</iyy>       <!-- for a box: iyy = 0.083 * mass * (x*x + z*z) -->
            <iyz>0.0</iyz>         <!-- for a box: iyz = 0 -->
            <izz>0.083</izz>       <!-- for a box: izz = 0.083 * mass * (x*x + y*y) -->
          </inertia>
        </inertial>
        <collision name="collision">
          <geometry>
            <box>
              <size>1 1 1</size>
            </box>
          </geometry>
        </collision>
        <visual name="visual">
          <geometry>
            <box>
              <size>1 1 1</size>
            </box>
          </geometry>
        </visual>
      </link>
    </model>

    <model name="simple_gripper">
            <link name="riser">
                <pose>-0.15 0.0 0.5 0 0 0</pose>
                <inertial>
                    <pose>0 0 -0.5 0 0 0</pose>
                    <inertia>
                        <ixx>0.01</ixx>
                        <ixy>0</ixy>
                        <ixz>0</ixz>
                        <iyy>0.01</iyy>
                        <iyz>0</iyz>
                        <izz>0.01</izz>
                    </inertia>
                    <mass>10.0</mass>
                </inertial>
                <collision name="collision">
                    <geometry>
                        <box>
                            <size>0.2 0.2 1.0</size>
                        </box>
                    </geometry>
                </collision>
                <visual name="visual">
                    <geometry>
                        <box>
                            <size>0.2 0.2 1.0</size>
                        </box>
                    </geometry>
                    <material>
                        <script>Gazebo/Purple</script>
                    </material>
                </visual>
            </link>
            <link name="palm">
                <pose>0.0 0.0 0.05 0 0 0</pose>
                <inertial>
                    <inertia>
                        <ixx>0.01</ixx>
                        <ixy>0</ixy>
                        <ixz>0</ixz>
                        <iyy>0.01</iyy>
                        <iyz>0</iyz>
                        <izz>0.01</izz>
                    </inertia>
                    <mass>0.5</mass>
                </inertial>
                <collision name="collision">
                    <geometry>
                        <box>
                            <size>0.1 0.2 0.1</size>
                        </box>
                    </geometry>
                </collision>
                <visual name="visual">
                    <geometry>
                        <box>
                            <size>0.1 0.2 0.1</size>
                        </box>
                    </geometry>
                    <material>
                        <script>Gazebo/Red</script>
                    </material>
                </visual>
            </link>
            <link name="left_finger">
                <pose>0.1 0.2 0.05 0 0 -0.78539</pose>
                <inertial>
                    <inertia>
                        <ixx>0.01</ixx>
                        <ixy>0</ixy>
                        <ixz>0</ixz>
                        <iyy>0.01</iyy>
                        <iyz>0</iyz>
                        <izz>0.01</izz>
                    </inertia>
                    <mass>0.1</mass>
                </inertial>
                <collision name="collision">
                    <geometry>
                        <box>
                            <size>0.1 0.3 0.1</size>
                        </box>
                    </geometry>
                </collision>
                <visual name="visual">
                    <geometry>
                        <box>
                            <size>0.1 0.3 0.1</size>
                        </box>
                    </geometry>
                    <material>
                        <script>Gazebo/Blue</script>
                    </material>
                </visual>
            </link>
            <link name="left_finger_tip">
                <pose>0.336 0.3 0.05 0 0 1.5707</pose>
                <inertial>
                    <inertia>
                        <ixx>0.01</ixx>
                        <ixy>0</ixy>
                        <ixz>0</ixz>
                        <iyy>0.01</iyy>
                        <iyz>0</iyz>
                        <izz>0.01</izz>
                    </inertia>
                    <mass>0.1</mass>
                </inertial>
                <collision name="collision">
                    <geometry>
                        <box>
                            <size>0.1 0.2 0.1</size>
                        </box>
                    </geometry>
                </collision>
                <visual name="visual">
                    <geometry>
                        <box>
                            <size>0.1 0.2 0.1</size>
                        </box>
                    </geometry>
                    <material>
                        <script>Gazebo/Blue</script>
                    </material>
                </visual>
            </link>
            <link name="right_finger">
                <pose>0.1 -0.2 0.05 0 0 .78539</pose>
                <inertial>
                    <inertia>
                        <ixx>0.01</ixx>
                        <ixy>0</ixy>
                        <ixz>0</ixz>
                        <iyy>0.01</iyy>
                        <iyz>0</iyz>
                        <izz>0.01</izz>
                    </inertia>
                    <mass>0.1</mass>
                </inertial>
                <collision name="collision">
                    <geometry>
                        <box>
                            <size>0.1 0.3 0.1</size>
                        </box>
                    </geometry>
                </collision>
                <visual name="visual">
                    <geometry>
                        <box>
                            <size>0.1 0.3 0.1</size>
                        </box>
                    </geometry>
                    <material>
                        <script>Gazebo/Green</script>
                    </material>
                </visual>
            </link>
            <link name="right_finger_tip">
                <pose>0.336 -0.3 0.05 0 0 1.5707</pose>
                <inertial>
                    <inertia>
                        <ixx>0.01</ixx>
                        <ixy>0</ixy>
                        <ixz>0</ixz>
                        <iyy>0.01</iyy>
                        <iyz>0</iyz>
                        <izz>0.01</izz>
                    </inertia>
                    <mass>0.1</mass>
                </inertial>
                <collision name="collision">
                    <geometry>
                        <box>
                            <size>0.1 0.2 0.1</size>
                        </box>
                    </geometry>
                </collision>
                <visual name="visual">
                    <geometry>
                        <box>
                            <size>0.1 0.2 0.1</size>
                        </box>
                    </geometry>
                    <material>
                        <script>Gazebo/Green</script>
                    </material>
                </visual>
            </link>
            <static>true</static>

            <joint name="palm_left_finger" type="revolute">
                <pose>0 -0.15 0 0 0 0</pose>
                <child>left_finger</child>
                <parent>palm</parent>
                <axis>
                    <limit>
                        <lower>-0.4</lower>
                        <upper>0.4</upper>
                    </limit>
                    <xyz>0 0 1</xyz>
                </axis>
            </joint>
            <joint name="left_finger_tip" type="revolute">
                <pose>0 0.1 0 0 0 0</pose>
                <child>left_finger_tip</child>
                <parent>left_finger</parent>
                <axis>
                    <limit>
                        <lower>-0.4</lower>
                        <upper>0.4</upper>
                    </limit>
                    <xyz>0 0 1</xyz>
                </axis>
            </joint>
            <joint name="palm_right_finger" type="revolute">
                <pose>0 0.15 0 0 0 0</pose>
                <child>right_finger</child>
                <parent>palm</parent>
                <axis>
                    <limit>
                        <lower>-0.4</lower>
                        <upper>0.4</upper>
                    </limit>
                    <xyz>0 0 1</xyz>
                </axis>
            </joint>
            <joint name="right_finger_tip" type="revolute">
                <pose>0 0.1 0 0 0 0</pose>
                <child>right_finger_tip</child>
                <parent>right_finger</parent>
                <axis>
                    <limit>
                        <lower>-0.4</lower>
                        <upper>0.4</upper>
                    </limit>
                    <xyz>0 0 1</xyz>
                </axis>
            </joint>
            <joint name="palm_riser" type="prismatic">
                <child>palm</child>
                <parent>riser</parent>
                <axis>
                    <limit>
                        <lower>0</lower>
                        <upper>0.9</upper>
                    </limit>
                    <xyz>0 0 1</xyz>
                </axis>
            </joint>
    </model>
  </world>
</sdf>
